setblock ~1 ~0 ~1 stripped_birch_log
setblock ~1 ~0 ~1 stripped_birch_log
setblock ~1 ~1 ~1 stripped_birch_log
setblock ~1 ~2 ~1 stripped_birch_log
setblock ~1 ~3 ~1 stripped_birch_log
setblock ~1 ~4 ~1 stripped_birch_log
setblock ~1 ~5 ~1 stripped_birch_log
setblock ~1 ~6 ~1 stripped_birch_log
setblock ~1 ~7 ~1 stripped_birch_log
setblock ~1 ~8 ~1 stripped_birch_log
setblock ~1 ~8 ~1 stripped_birch_log
setblock ~1 ~0 ~2 stripped_birch_log
setblock ~1 ~4 ~2 stripped_birch_log
setblock ~1 ~8 ~2 stripped_birch_log
setblock ~1 ~0 ~3 stripped_birch_log
setblock ~1 ~4 ~3 stripped_birch_log
setblock ~1 ~8 ~3 stripped_birch_log
setblock ~1 ~0 ~4 stripped_birch_log
setblock ~1 ~4 ~4 stripped_birch_log
setblock ~1 ~8 ~4 stripped_birch_log
setblock ~1 ~0 ~5 stripped_birch_log
setblock ~1 ~4 ~5 stripped_birch_log
setblock ~1 ~8 ~5 stripped_birch_log
setblock ~1 ~0 ~6 stripped_birch_log
setblock ~1 ~0 ~6 stripped_birch_log
setblock ~1 ~1 ~6 stripped_birch_log
setblock ~1 ~2 ~6 stripped_birch_log
setblock ~1 ~3 ~6 stripped_birch_log
setblock ~1 ~4 ~6 stripped_birch_log
setblock ~1 ~4 ~6 stripped_birch_log
setblock ~1 ~5 ~6 stripped_birch_log
setblock ~1 ~6 ~6 stripped_birch_log
setblock ~1 ~7 ~6 stripped_birch_log
setblock ~1 ~8 ~6 stripped_birch_log
setblock ~1 ~8 ~6 stripped_birch_log
setblock ~1 ~0 ~7 stripped_birch_log
setblock ~1 ~4 ~7 stripped_birch_log
setblock ~1 ~8 ~7 stripped_birch_log
setblock ~1 ~0 ~8 stripped_birch_log
setblock ~1 ~4 ~8 stripped_birch_log
setblock ~1 ~8 ~8 stripped_birch_log
setblock ~1 ~0 ~9 stripped_birch_log
setblock ~1 ~0 ~9 stripped_birch_log
setblock ~1 ~0 ~9 stripped_birch_log
setblock ~1 ~1 ~9 stripped_birch_log
setblock ~1 ~1 ~9 stripped_birch_log
setblock ~1 ~2 ~9 stripped_birch_log
setblock ~1 ~2 ~9 stripped_birch_log
setblock ~1 ~3 ~9 stripped_birch_log
setblock ~1 ~3 ~9 stripped_birch_log
setblock ~1 ~4 ~9 stripped_birch_log
setblock ~1 ~4 ~9 stripped_birch_log
setblock ~1 ~4 ~9 stripped_birch_log
setblock ~1 ~5 ~9 stripped_birch_log
setblock ~1 ~5 ~9 stripped_birch_log
setblock ~1 ~6 ~9 stripped_birch_log
setblock ~1 ~6 ~9 stripped_birch_log
setblock ~1 ~7 ~9 stripped_birch_log
setblock ~1 ~7 ~9 stripped_birch_log
setblock ~1 ~8 ~9 stripped_birch_log
setblock ~1 ~8 ~9 stripped_birch_log
setblock ~1 ~8 ~9 stripped_birch_log
setblock ~2 ~0 ~1 stripped_birch_log
setblock ~2 ~8 ~1 stripped_birch_log
setblock ~2 ~0 ~9 stripped_birch_log
setblock ~2 ~1 ~9 birch_stairs[half=top,facing=north]
setblock ~2 ~2 ~9 birch_stairs[half=top,facing=north]
setblock ~2 ~3 ~9 birch_stairs[half=top,facing=north]
setblock ~2 ~4 ~9 stripped_birch_log
setblock ~2 ~5 ~9 birch_leaves
setblock ~2 ~6 ~9 birch_leaves
setblock ~2 ~7 ~9 birch_leaves
setblock ~2 ~8 ~9 stripped_birch_log
setblock ~3 ~0 ~1 stripped_birch_log
setblock ~3 ~8 ~1 stripped_birch_log
setblock ~3 ~0 ~9 stripped_birch_log
setblock ~3 ~0 ~9 stripped_birch_log
setblock ~3 ~1 ~9 stripped_birch_log
setblock ~3 ~2 ~9 stripped_birch_log
setblock ~3 ~3 ~9 stripped_birch_log
setblock ~3 ~4 ~9 stripped_birch_log
setblock ~3 ~4 ~9 stripped_birch_log
setblock ~3 ~5 ~9 stripped_birch_log
setblock ~3 ~6 ~9 stripped_birch_log
setblock ~3 ~7 ~9 stripped_birch_log
setblock ~3 ~8 ~9 stripped_birch_log
setblock ~3 ~8 ~9 stripped_birch_log
setblock ~4 ~0 ~1 stripped_birch_log
setblock ~4 ~8 ~1 stripped_birch_log
setblock ~4 ~0 ~9 stripped_birch_log
setblock ~4 ~1 ~9 birch_stairs[half=top,facing=north]
setblock ~4 ~2 ~9 birch_stairs[half=top,facing=north]
setblock ~4 ~3 ~9 birch_stairs[half=top,facing=north]
setblock ~4 ~4 ~9 stripped_birch_log
setblock ~4 ~5 ~9 birch_leaves
setblock ~4 ~6 ~9 birch_leaves
setblock ~4 ~7 ~9 birch_leaves
setblock ~4 ~8 ~9 stripped_birch_log
setblock ~5 ~0 ~1 stripped_birch_log
setblock ~5 ~8 ~1 stripped_birch_log
setblock ~5 ~0 ~9 stripped_birch_log
setblock ~5 ~0 ~9 stripped_birch_log
setblock ~5 ~1 ~9 stripped_birch_log
setblock ~5 ~2 ~9 stripped_birch_log
setblock ~5 ~3 ~9 stripped_birch_log
setblock ~5 ~4 ~9 stripped_birch_log
setblock ~5 ~4 ~9 stripped_birch_log
setblock ~5 ~5 ~9 stripped_birch_log
setblock ~5 ~6 ~9 stripped_birch_log
setblock ~5 ~7 ~9 stripped_birch_log
setblock ~5 ~8 ~9 stripped_birch_log
setblock ~5 ~8 ~9 stripped_birch_log
setblock ~6 ~0 ~1 stripped_birch_log
setblock ~6 ~8 ~1 stripped_birch_log
setblock ~6 ~0 ~9 stripped_birch_log
setblock ~6 ~1 ~9 birch_stairs[half=top,facing=north]
setblock ~6 ~2 ~9 birch_stairs[half=top,facing=north]
setblock ~6 ~3 ~9 birch_stairs[half=top,facing=north]
setblock ~6 ~4 ~9 stripped_birch_log
setblock ~6 ~5 ~9 birch_leaves
setblock ~6 ~6 ~9 birch_leaves
setblock ~6 ~7 ~9 birch_leaves
setblock ~6 ~8 ~9 stripped_birch_log
setblock ~7 ~0 ~1 stripped_birch_log
setblock ~7 ~8 ~1 stripped_birch_log
setblock ~7 ~0 ~9 stripped_birch_log
setblock ~7 ~0 ~9 stripped_birch_log
setblock ~7 ~1 ~9 stripped_birch_log
setblock ~7 ~2 ~9 stripped_birch_log
setblock ~7 ~3 ~9 stripped_birch_log
setblock ~7 ~4 ~9 stripped_birch_log
setblock ~7 ~4 ~9 stripped_birch_log
setblock ~7 ~5 ~9 stripped_birch_log
setblock ~7 ~6 ~9 stripped_birch_log
setblock ~7 ~7 ~9 stripped_birch_log
setblock ~7 ~8 ~9 stripped_birch_log
setblock ~7 ~8 ~9 stripped_birch_log
setblock ~8 ~0 ~1 stripped_birch_log
setblock ~8 ~8 ~1 stripped_birch_log
setblock ~8 ~0 ~9 stripped_birch_log
setblock ~8 ~1 ~9 birch_stairs[half=top,facing=north]
setblock ~8 ~2 ~9 birch_stairs[half=top,facing=north]
setblock ~8 ~3 ~9 birch_stairs[half=top,facing=north]
setblock ~8 ~4 ~9 stripped_birch_log
setblock ~8 ~5 ~9 birch_leaves
setblock ~8 ~6 ~9 birch_leaves
setblock ~8 ~7 ~9 birch_leaves
setblock ~8 ~8 ~9 stripped_birch_log
setblock ~9 ~0 ~1 stripped_birch_log
setblock ~9 ~0 ~1 stripped_birch_log
setblock ~9 ~1 ~1 stripped_birch_log
setblock ~9 ~2 ~1 stripped_birch_log
setblock ~9 ~3 ~1 stripped_birch_log
setblock ~9 ~4 ~1 stripped_birch_log
setblock ~9 ~5 ~1 stripped_birch_log
setblock ~9 ~6 ~1 stripped_birch_log
setblock ~9 ~7 ~1 stripped_birch_log
setblock ~9 ~8 ~1 stripped_birch_log
setblock ~9 ~8 ~1 stripped_birch_log
setblock ~9 ~0 ~2 stripped_birch_log
setblock ~9 ~4 ~2 stripped_birch_log
setblock ~9 ~8 ~2 stripped_birch_log
setblock ~9 ~0 ~3 stripped_birch_log
setblock ~9 ~4 ~3 stripped_birch_log
setblock ~9 ~8 ~3 stripped_birch_log
setblock ~9 ~0 ~4 stripped_birch_log
setblock ~9 ~4 ~4 stripped_birch_log
setblock ~9 ~8 ~4 stripped_birch_log
setblock ~9 ~0 ~5 stripped_birch_log
setblock ~9 ~4 ~5 stripped_birch_log
setblock ~9 ~8 ~5 stripped_birch_log
setblock ~9 ~0 ~6 stripped_birch_log
setblock ~9 ~0 ~6 stripped_birch_log
setblock ~9 ~1 ~6 stripped_birch_log
setblock ~9 ~2 ~6 stripped_birch_log
setblock ~9 ~3 ~6 stripped_birch_log
setblock ~9 ~4 ~6 stripped_birch_log
setblock ~9 ~4 ~6 stripped_birch_log
setblock ~9 ~5 ~6 stripped_birch_log
setblock ~9 ~6 ~6 stripped_birch_log
setblock ~9 ~7 ~6 stripped_birch_log
setblock ~9 ~8 ~6 stripped_birch_log
setblock ~9 ~8 ~6 stripped_birch_log
setblock ~9 ~0 ~7 stripped_birch_log
setblock ~9 ~4 ~7 stripped_birch_log
setblock ~9 ~8 ~7 stripped_birch_log
setblock ~9 ~0 ~8 stripped_birch_log
setblock ~9 ~4 ~8 stripped_birch_log
setblock ~9 ~8 ~8 stripped_birch_log
setblock ~9 ~0 ~9 stripped_birch_log
setblock ~9 ~0 ~9 stripped_birch_log
setblock ~9 ~0 ~9 stripped_birch_log
setblock ~9 ~1 ~9 stripped_birch_log
setblock ~9 ~1 ~9 stripped_birch_log
setblock ~9 ~2 ~9 stripped_birch_log
setblock ~9 ~2 ~9 stripped_birch_log
setblock ~9 ~3 ~9 stripped_birch_log
setblock ~9 ~3 ~9 stripped_birch_log
setblock ~9 ~4 ~9 stripped_birch_log
setblock ~9 ~4 ~9 stripped_birch_log
setblock ~9 ~4 ~9 stripped_birch_log
setblock ~9 ~5 ~9 stripped_birch_log
setblock ~9 ~5 ~9 stripped_birch_log
setblock ~9 ~6 ~9 stripped_birch_log
setblock ~9 ~6 ~9 stripped_birch_log
setblock ~9 ~7 ~9 stripped_birch_log
setblock ~9 ~7 ~9 stripped_birch_log
setblock ~9 ~8 ~9 stripped_birch_log
setblock ~9 ~8 ~9 stripped_birch_log
setblock ~9 ~8 ~9 stripped_birch_log
setblock ~2 ~0 ~2 birch_planks
setblock ~2 ~0 ~3 dark_oak_planks
setblock ~2 ~0 ~4 birch_planks
setblock ~2 ~0 ~5 dark_oak_planks
setblock ~2 ~0 ~6 birch_planks
setblock ~2 ~0 ~7 dark_oak_planks
setblock ~2 ~0 ~8 birch_planks
setblock ~3 ~0 ~2 dark_oak_planks
setblock ~3 ~0 ~3 birch_planks
setblock ~3 ~0 ~4 dark_oak_planks
setblock ~3 ~0 ~5 birch_planks
setblock ~3 ~0 ~6 dark_oak_planks
setblock ~3 ~0 ~7 birch_planks
setblock ~3 ~0 ~8 dark_oak_planks
setblock ~4 ~0 ~2 birch_planks
setblock ~4 ~0 ~3 dark_oak_planks
setblock ~4 ~0 ~4 birch_planks
setblock ~4 ~0 ~5 dark_oak_planks
setblock ~4 ~0 ~6 birch_planks
setblock ~4 ~0 ~7 dark_oak_planks
setblock ~4 ~0 ~8 birch_planks
setblock ~5 ~0 ~2 dark_oak_planks
setblock ~5 ~0 ~3 birch_planks
setblock ~5 ~0 ~4 dark_oak_planks
setblock ~5 ~0 ~5 birch_planks
setblock ~5 ~0 ~6 dark_oak_planks
setblock ~5 ~0 ~7 birch_planks
setblock ~5 ~0 ~8 dark_oak_planks
setblock ~6 ~0 ~2 birch_planks
setblock ~6 ~0 ~3 dark_oak_planks
setblock ~6 ~0 ~4 birch_planks
setblock ~6 ~0 ~5 dark_oak_planks
setblock ~6 ~0 ~6 birch_planks
setblock ~6 ~0 ~7 dark_oak_planks
setblock ~6 ~0 ~8 birch_planks
setblock ~7 ~0 ~2 dark_oak_planks
setblock ~7 ~0 ~3 birch_planks
setblock ~7 ~0 ~4 dark_oak_planks
setblock ~7 ~0 ~5 birch_planks
setblock ~7 ~0 ~6 dark_oak_planks
setblock ~7 ~0 ~7 birch_planks
setblock ~7 ~0 ~8 dark_oak_planks
setblock ~8 ~0 ~2 birch_planks
setblock ~8 ~0 ~3 dark_oak_planks
setblock ~8 ~0 ~4 birch_planks
setblock ~8 ~0 ~5 dark_oak_planks
setblock ~8 ~0 ~6 birch_planks
setblock ~8 ~0 ~7 dark_oak_planks
setblock ~8 ~0 ~8 birch_planks
setblock ~2 ~1 ~1 glass_pane
setblock ~2 ~2 ~1 glass_pane
setblock ~2 ~3 ~1 glass_pane
setblock ~2 ~4 ~1 glass_pane
setblock ~2 ~5 ~1 glass_pane
setblock ~2 ~6 ~1 glass_pane
setblock ~2 ~7 ~1 glass_pane
setblock ~3 ~1 ~1 glass_pane
setblock ~3 ~2 ~1 glass_pane
setblock ~3 ~3 ~1 glass_pane
setblock ~3 ~4 ~1 glass_pane
setblock ~3 ~5 ~1 glass_pane
setblock ~3 ~6 ~1 glass_pane
setblock ~3 ~7 ~1 glass_pane
setblock ~4 ~1 ~1 glass_pane
setblock ~4 ~2 ~1 glass_pane
setblock ~4 ~3 ~1 glass_pane
setblock ~4 ~4 ~1 glass_pane
setblock ~4 ~5 ~1 glass_pane
setblock ~4 ~6 ~1 glass_pane
setblock ~4 ~7 ~1 glass_pane
setblock ~5 ~1 ~1 glass_pane
setblock ~5 ~2 ~1 glass_pane
setblock ~5 ~3 ~1 glass_pane
setblock ~5 ~4 ~1 glass_pane
setblock ~5 ~5 ~1 glass_pane
setblock ~5 ~6 ~1 glass_pane
setblock ~5 ~7 ~1 glass_pane
setblock ~6 ~1 ~1 glass_pane
setblock ~6 ~2 ~1 glass_pane
setblock ~6 ~3 ~1 glass_pane
setblock ~6 ~4 ~1 glass_pane
setblock ~6 ~5 ~1 glass_pane
setblock ~6 ~6 ~1 glass_pane
setblock ~6 ~7 ~1 glass_pane
setblock ~7 ~1 ~1 glass_pane
setblock ~7 ~2 ~1 glass_pane
setblock ~7 ~3 ~1 glass_pane
setblock ~7 ~4 ~1 glass_pane
setblock ~7 ~5 ~1 glass_pane
setblock ~7 ~6 ~1 glass_pane
setblock ~7 ~7 ~1 glass_pane
setblock ~8 ~1 ~1 glass_pane
setblock ~8 ~2 ~1 glass_pane
setblock ~8 ~3 ~1 glass_pane
setblock ~8 ~4 ~1 glass_pane
setblock ~8 ~5 ~1 glass_pane
setblock ~8 ~6 ~1 glass_pane
setblock ~8 ~7 ~1 glass_pane
setblock ~1 ~1 ~2 birch_planks
setblock ~1 ~2 ~2 birch_planks
setblock ~1 ~3 ~2 birch_planks
setblock ~1 ~5 ~2 glass_pane
setblock ~1 ~6 ~2 glass_pane
setblock ~1 ~7 ~2 glass_pane
setblock ~1 ~1 ~3 birch_planks
setblock ~1 ~2 ~3 birch_planks
setblock ~1 ~3 ~3 birch_planks
setblock ~1 ~5 ~3 glass_pane
setblock ~1 ~6 ~3 glass_pane
setblock ~1 ~7 ~3 glass_pane
setblock ~1 ~1 ~4 birch_planks
setblock ~1 ~2 ~4 birch_planks
setblock ~1 ~3 ~4 birch_planks
setblock ~1 ~5 ~4 glass_pane
setblock ~1 ~6 ~4 glass_pane
setblock ~1 ~7 ~4 glass_pane
setblock ~1 ~1 ~5 birch_planks
setblock ~1 ~2 ~5 birch_planks
setblock ~1 ~3 ~5 birch_planks
setblock ~1 ~5 ~5 glass_pane
setblock ~1 ~6 ~5 glass_pane
setblock ~1 ~7 ~5 glass_pane
setblock ~9 ~1 ~2 birch_planks
setblock ~9 ~2 ~2 birch_planks
setblock ~9 ~3 ~2 birch_planks
setblock ~9 ~5 ~2 glass_pane
setblock ~9 ~6 ~2 glass_pane
setblock ~9 ~7 ~2 glass_pane
setblock ~9 ~1 ~3 birch_planks
setblock ~9 ~2 ~3 birch_planks
setblock ~9 ~3 ~3 birch_planks
setblock ~9 ~5 ~3 glass_pane
setblock ~9 ~6 ~3 glass_pane
setblock ~9 ~7 ~3 glass_pane
setblock ~9 ~1 ~4 birch_planks
setblock ~9 ~2 ~4 birch_planks
setblock ~9 ~3 ~4 birch_planks
setblock ~9 ~5 ~4 glass_pane
setblock ~9 ~6 ~4 glass_pane
setblock ~9 ~7 ~4 glass_pane
setblock ~9 ~1 ~5 birch_planks
setblock ~9 ~2 ~5 birch_planks
setblock ~9 ~3 ~5 birch_planks
setblock ~9 ~5 ~5 glass_pane
setblock ~9 ~6 ~5 glass_pane
setblock ~9 ~7 ~5 glass_pane
setblock ~1 ~1 ~7 birch_stairs[half=top,facing=east]
setblock ~1 ~2 ~7 birch_stairs[half=top,facing=east]
setblock ~1 ~3 ~7 birch_stairs[half=top,facing=east]
setblock ~1 ~1 ~8 birch_stairs[half=top,facing=east]
setblock ~1 ~2 ~8 birch_stairs[half=top,facing=east]
setblock ~1 ~3 ~8 birch_stairs[half=top,facing=east]
setblock ~9 ~1 ~7 birch_stairs[half=top,facing=west]
setblock ~9 ~2 ~7 birch_stairs[half=top,facing=west]
setblock ~9 ~3 ~7 birch_stairs[half=top,facing=west]
setblock ~9 ~5 ~7 birch_stairs[half=top,facing=west]
setblock ~9 ~6 ~7 birch_stairs[half=top,facing=west]
setblock ~9 ~7 ~7 birch_stairs[half=top,facing=west]
setblock ~9 ~1 ~8 birch_stairs[half=top,facing=west]
setblock ~9 ~2 ~8 birch_stairs[half=top,facing=west]
setblock ~9 ~3 ~8 birch_stairs[half=top,facing=west]
setblock ~9 ~5 ~8 birch_stairs[half=top,facing=west]
setblock ~9 ~6 ~8 birch_stairs[half=top,facing=west]
setblock ~9 ~7 ~8 birch_stairs[half=top,facing=west]
setblock ~2 ~4 ~8 birch_slab[type=top]
setblock ~3 ~4 ~8 birch_slab[type=top]
setblock ~4 ~4 ~5 birch_slab[type=top]
setblock ~4 ~4 ~6 birch_slab[type=top]
setblock ~4 ~4 ~7 birch_slab[type=top]
setblock ~4 ~4 ~8 birch_slab[type=top]
setblock ~5 ~4 ~5 birch_slab[type=top]
setblock ~5 ~4 ~6 birch_slab[type=top]
setblock ~5 ~4 ~7 birch_slab[type=top]
setblock ~5 ~4 ~8 birch_slab[type=top]
setblock ~6 ~4 ~5 birch_slab[type=top]
setblock ~6 ~4 ~6 birch_slab[type=top]
setblock ~6 ~4 ~7 birch_slab[type=top]
setblock ~6 ~4 ~8 birch_slab[type=top]
setblock ~7 ~4 ~5 birch_slab[type=top]
setblock ~7 ~4 ~6 birch_slab[type=top]
setblock ~7 ~4 ~7 birch_slab[type=top]
setblock ~7 ~4 ~8 birch_slab[type=top]
setblock ~8 ~4 ~5 birch_slab[type=top]
setblock ~8 ~4 ~6 birch_slab[type=top]
setblock ~8 ~4 ~7 birch_slab[type=top]
setblock ~8 ~4 ~8 birch_slab[type=top]
setblock ~4 ~5 ~5 birch_fence
setblock ~5 ~5 ~5 birch_fence
setblock ~6 ~5 ~5 birch_fence
setblock ~7 ~5 ~5 birch_fence
setblock ~8 ~5 ~5 birch_fence
setblock ~4 ~5 ~6 birch_fence
setblock ~0 ~0 ~2 oak_stairs[facing=south]
setblock ~0 ~1 ~3 oak_stairs[facing=south]
setblock ~0 ~2 ~4 oak_stairs[facing=south]
setblock ~0 ~3 ~5 oak_stairs[facing=south]
setblock ~0 ~4 ~6 oak_stairs[facing=south]
setblock ~-1 ~0 ~2 oak_stairs[facing=south]
setblock ~-1 ~1 ~3 oak_stairs[facing=south]
setblock ~-1 ~2 ~4 oak_stairs[facing=south]
setblock ~-1 ~3 ~5 oak_stairs[facing=south]
setblock ~-1 ~4 ~6 oak_stairs[facing=south]
setblock ~0 ~4 ~7 oak_planks
setblock ~0 ~4 ~8 oak_planks
setblock ~0 ~4 ~9 oak_planks
setblock ~-1 ~4 ~7 oak_planks
setblock ~-1 ~4 ~8 oak_planks
setblock ~-1 ~4 ~9 oak_planks
setblock ~3 ~8 ~2 stripped_birch_log
setblock ~3 ~8 ~3 stripped_birch_log
setblock ~3 ~8 ~4 stripped_birch_log
setblock ~3 ~8 ~5 stripped_birch_log
setblock ~3 ~8 ~6 stripped_birch_log
setblock ~3 ~8 ~7 stripped_birch_log
setblock ~3 ~8 ~8 stripped_birch_log
setblock ~5 ~8 ~2 stripped_birch_log
setblock ~5 ~8 ~3 stripped_birch_log
setblock ~5 ~8 ~4 stripped_birch_log
setblock ~5 ~8 ~5 stripped_birch_log
setblock ~5 ~8 ~6 stripped_birch_log
setblock ~5 ~8 ~7 stripped_birch_log
setblock ~5 ~8 ~8 stripped_birch_log
setblock ~7 ~8 ~2 stripped_birch_log
setblock ~7 ~8 ~3 stripped_birch_log
setblock ~7 ~8 ~4 stripped_birch_log
setblock ~7 ~8 ~5 stripped_birch_log
setblock ~7 ~8 ~6 stripped_birch_log
setblock ~7 ~8 ~7 stripped_birch_log
setblock ~7 ~8 ~8 stripped_birch_log
setblock ~-2 ~0 ~2 stripped_birch_log
setblock ~-2 ~0 ~3 stripped_birch_log
setblock ~-2 ~1 ~3 stripped_birch_log
setblock ~-2 ~0 ~4 stripped_birch_log
setblock ~-2 ~1 ~4 stripped_birch_log
setblock ~-2 ~2 ~4 stripped_birch_log
setblock ~-2 ~0 ~5 stripped_birch_log
setblock ~-2 ~1 ~5 stripped_birch_log
setblock ~-2 ~2 ~5 stripped_birch_log
setblock ~-2 ~3 ~5 stripped_birch_log
setblock ~-2 ~0 ~6 stripped_birch_log
setblock ~-2 ~1 ~6 stripped_birch_log
setblock ~-2 ~2 ~6 stripped_birch_log
setblock ~-2 ~3 ~6 stripped_birch_log
setblock ~-2 ~4 ~6 stripped_birch_log
setblock ~-2 ~0 ~7 stripped_birch_log
setblock ~-2 ~1 ~7 stripped_birch_log
setblock ~-2 ~2 ~7 stripped_birch_log
setblock ~-2 ~3 ~7 stripped_birch_log
setblock ~-2 ~4 ~7 stripped_birch_log
setblock ~-2 ~0 ~8 stripped_birch_log
setblock ~-2 ~1 ~8 stripped_birch_log
setblock ~-2 ~2 ~8 stripped_birch_log
setblock ~-2 ~3 ~8 stripped_birch_log
setblock ~-2 ~4 ~8 stripped_birch_log
setblock ~-2 ~0 ~9 stripped_birch_log
setblock ~-2 ~1 ~9 stripped_birch_log
setblock ~-2 ~2 ~9 stripped_birch_log
setblock ~-2 ~3 ~9 stripped_birch_log
setblock ~-2 ~4 ~9 stripped_birch_log
setblock ~0 ~0 ~9 stripped_birch_log
setblock ~0 ~1 ~9 stripped_birch_log
setblock ~0 ~2 ~9 stripped_birch_log
setblock ~0 ~3 ~9 stripped_birch_log
setblock ~0 ~4 ~9 stripped_birch_log
setblock ~-1 ~0 ~9 stripped_birch_log
setblock ~-1 ~1 ~9 stripped_birch_log
setblock ~-1 ~2 ~9 stripped_birch_log
setblock ~-1 ~3 ~9 stripped_birch_log
setblock ~-1 ~4 ~9 stripped_birch_log
setblock ~1 ~0 ~0 oak_fence
setblock ~1 ~0 ~-1 oak_fence
setblock ~1 ~0 ~-2 oak_fence
setblock ~1 ~0 ~-3 oak_fence
setblock ~1 ~0 ~-4 oak_fence
setblock ~-2 ~0 ~1 oak_fence
setblock ~-2 ~0 ~0 oak_fence
setblock ~-2 ~0 ~-1 oak_fence
setblock ~-2 ~0 ~-2 oak_fence
setblock ~-2 ~0 ~-3 oak_fence
setblock ~-2 ~0 ~-4 oak_fence
setblock ~0 ~0 ~0 brown_carpet
setblock ~0 ~0 ~-2 brown_carpet
setblock ~0 ~0 ~-4 brown_carpet
setblock ~-1 ~0 ~0 brown_carpet
setblock ~-1 ~0 ~-2 brown_carpet
setblock ~-1 ~0 ~-4 brown_carpet
setblock ~0 ~5 ~9 oak_fence
setblock ~-1 ~5 ~9 oak_fence
setblock ~-2 ~5 ~6 oak_fence
setblock ~-2 ~6 ~6 oak_fence
setblock ~-2 ~7 ~6 oak_fence
setblock ~-2 ~5 ~7 oak_fence
setblock ~-2 ~5 ~8 oak_fence
setblock ~-2 ~5 ~9 oak_fence
setblock ~-2 ~6 ~9 oak_fence
setblock ~-2 ~7 ~9 oak_fence
setblock ~0 ~8 ~6 oak_slab
setblock ~0 ~8 ~7 oak_slab
setblock ~0 ~8 ~8 oak_slab
setblock ~0 ~8 ~9 oak_slab
setblock ~-1 ~8 ~6 oak_slab
setblock ~-1 ~8 ~7 oak_slab
setblock ~-1 ~8 ~8 oak_slab
setblock ~-1 ~8 ~9 oak_slab
setblock ~-2 ~8 ~6 oak_slab
setblock ~-2 ~8 ~7 oak_slab
setblock ~-2 ~8 ~8 oak_slab
setblock ~-2 ~8 ~9 oak_slab
setblock ~-2 ~1 ~2 spruce_trapdoor[facing=east]
setblock ~-2 ~2 ~3 spruce_trapdoor[facing=east]
setblock ~-2 ~3 ~4 spruce_trapdoor[facing=east]
setblock ~-2 ~4 ~5 spruce_trapdoor[facing=east]
setblock ~-3 ~0 ~4 composter
setblock ~-3 ~0 ~6 composter
setblock ~-3 ~0 ~8 composter
setblock ~2 ~-1 ~0 grass_block
setblock ~2 ~-1 ~-1 grass_block
setblock ~2 ~-1 ~-2 grass_block
setblock ~2 ~-1 ~-3 grass_block
setblock ~2 ~-1 ~-4 grass_block
setblock ~2 ~-1 ~-5 grass_block
setblock ~3 ~-1 ~0 grass_block
setblock ~3 ~-1 ~-1 grass_block
setblock ~3 ~-1 ~-2 grass_block
setblock ~3 ~-1 ~-3 grass_block
setblock ~3 ~-1 ~-4 grass_block
setblock ~3 ~-1 ~-5 grass_block
setblock ~4 ~-1 ~0 grass_block
setblock ~4 ~-1 ~-1 grass_block
setblock ~4 ~-1 ~-2 grass_block
setblock ~4 ~-1 ~-3 grass_block
setblock ~4 ~-1 ~-4 grass_block
setblock ~4 ~-1 ~-5 grass_block
setblock ~5 ~-1 ~0 grass_block
setblock ~5 ~-1 ~-1 grass_block
setblock ~5 ~-1 ~-2 grass_block
setblock ~5 ~-1 ~-3 grass_block
setblock ~5 ~-1 ~-4 grass_block
setblock ~5 ~-1 ~-5 grass_block
setblock ~6 ~-1 ~0 grass_block
setblock ~6 ~-1 ~-1 grass_block
setblock ~6 ~-1 ~-2 grass_block
setblock ~6 ~-1 ~-3 grass_block
setblock ~6 ~-1 ~-4 grass_block
setblock ~6 ~-1 ~-5 grass_block
setblock ~7 ~-1 ~0 grass_block
setblock ~7 ~-1 ~-1 grass_block
setblock ~7 ~-1 ~-2 grass_block
setblock ~7 ~-1 ~-3 grass_block
setblock ~7 ~-1 ~-4 grass_block
setblock ~7 ~-1 ~-5 grass_block
setblock ~8 ~-1 ~0 grass_block
setblock ~8 ~-1 ~-1 grass_block
setblock ~8 ~-1 ~-2 grass_block
setblock ~8 ~-1 ~-3 grass_block
setblock ~8 ~-1 ~-4 grass_block
setblock ~8 ~-1 ~-5 grass_block
setblock ~9 ~-1 ~0 grass_block
setblock ~9 ~-1 ~-1 grass_block
setblock ~9 ~-1 ~-2 grass_block
setblock ~9 ~-1 ~-3 grass_block
setblock ~9 ~-1 ~-4 grass_block
setblock ~9 ~-1 ~-5 grass_block
setblock ~2 ~0 ~0 poppy
setblock ~2 ~0 ~-1 poppy
setblock ~2 ~0 ~-2 poppy
setblock ~2 ~0 ~-3 poppy
setblock ~2 ~0 ~-4 poppy
setblock ~2 ~0 ~-5 poppy
setblock ~3 ~0 ~0 poppy
setblock ~3 ~0 ~-1 poppy
setblock ~3 ~0 ~-2 poppy
setblock ~3 ~0 ~-3 poppy
setblock ~3 ~0 ~-4 poppy
setblock ~3 ~0 ~-5 poppy
setblock ~4 ~0 ~0 poppy
setblock ~4 ~0 ~-1 poppy
setblock ~4 ~0 ~-2 poppy
setblock ~4 ~0 ~-3 poppy
setblock ~4 ~0 ~-4 poppy
setblock ~4 ~0 ~-5 poppy
setblock ~5 ~0 ~0 poppy
setblock ~5 ~0 ~-1 poppy
setblock ~5 ~0 ~-2 poppy
setblock ~5 ~0 ~-3 poppy
setblock ~5 ~0 ~-4 poppy
setblock ~5 ~0 ~-5 poppy
setblock ~6 ~0 ~0 poppy
setblock ~6 ~0 ~-1 poppy
setblock ~6 ~0 ~-2 poppy
setblock ~6 ~0 ~-3 poppy
setblock ~6 ~0 ~-4 poppy
setblock ~6 ~0 ~-5 poppy
setblock ~7 ~0 ~0 poppy
setblock ~7 ~0 ~-1 poppy
setblock ~7 ~0 ~-2 poppy
setblock ~7 ~0 ~-3 poppy
setblock ~7 ~0 ~-4 poppy
setblock ~7 ~0 ~-5 poppy
setblock ~8 ~0 ~0 poppy
setblock ~8 ~0 ~-1 poppy
setblock ~8 ~0 ~-2 poppy
setblock ~8 ~0 ~-3 poppy
setblock ~8 ~0 ~-4 poppy
setblock ~8 ~0 ~-5 poppy
setblock ~9 ~0 ~0 poppy
setblock ~9 ~0 ~-1 poppy
setblock ~9 ~0 ~-2 poppy
setblock ~9 ~0 ~-3 poppy
setblock ~9 ~0 ~-4 poppy
setblock ~9 ~0 ~-5 poppy
setblock ~2 ~1 ~5 birch_slab[type=top]
setblock ~2 ~2 ~6 birch_slab[type=top]
setblock ~2 ~3 ~7 birch_slab[type=top]
setblock ~3 ~1 ~5 birch_slab[type=top]
setblock ~3 ~2 ~6 birch_slab[type=top]
setblock ~3 ~3 ~7 birch_slab[type=top]
